[0;31m---------------------------------------------------------------------------[0m
[0;31mExampleException[0m                          Traceback (most recent call last)
[0;32m/((( anything )))/story.py[0m in [0;36mrun_special_method[0;34m(self, method)[0m
[1;32m    154[0m         [0;32mtry[0m[0;34m:[0m[0;34m[0m[0m
[0;32m--> 155[0;31m             [0mmethod[0m[0;34m([0m[0;34m)[0m[0;34m[0m[0m
[0m[1;32m    156[0m         [0;32mexcept[0m [0mException[0m [0;32mas[0m [0mexception[0m[0;34m:[0m[0;34m[0m[0m

[0;32m/((( anything )))/engine.py[0m in [0;36mon_success[0;34m(self)[0m
[1;32m      8[0m     [0;32mdef[0m [0mon_success[0m[0;34m([0m[0mself[0m[0;34m)[0m[0;34m:[0m[0;34m[0m[0m
[0;32m----> 9[0;31m         [0mraise_example_exception[0m[0;34m([0m[0;34m)[0m[0;34m[0m[0m
[0m
[0;32m/((( anything )))/code_that_does_things.py[0m in [0;36mraise_example_exception[0;34m(text)[0m
[1;32m     22[0m [0;32mdef[0m [0mraise_example_exception[0m[0;34m([0m[0mtext[0m[0;34m=[0m[0;34m""[0m[0;34m)[0m[0;34m:[0m[0;34m[0m[0m
[0;32m---> 23[0;31m     [0;32mraise[0m [0mExampleException[0m[0;34m([0m[0mtext[0m[0;34m)[0m[0;34m[0m[0m
[0m[1;32m     24[0m [0;34m[0m[0m

[0;31mExampleException[0m: 

During handling of the above exception, another exception occurred:

[0;31mOnSuccessException[0m                        Traceback (most recent call last)
[0;32m<ipython-input-((( anything )))>[0m in [0;36m<module>[0;34m()[0m
[0;32m----> 1[0;31m [0mStoryCollection[0m[0;34m([0m[0mpathq[0m[0;34m([0m[0;34m"."[0m[0;34m)[0m[0;34m.[0m[0mext[0m[0;34m([0m[0;34m"story"[0m[0;34m)[0m[0;34m,[0m [0mEngine[0m[0;34m([0m[0;34m)[0m[0;34m)[0m[0;34m.[0m[0mone[0m[0;34m([0m[0;34m)[0m[0;34m.[0m[0mplay[0m[0;34m([0m[0;34m)[0m[0;34m[0m[0m
[0m
[0;32m/((( anything )))/story.py[0m in [0;36mplay[0;34m(self)[0m
[1;32m    177[0m [0;34m[0m[0m
[1;32m    178[0m         [0;32mif[0m [0mpassed[0m[0;34m:[0m[0;34m[0m[0m
[0;32m--> 179[0;31m             [0mself[0m[0;34m.[0m[0mrun_special_method[0m[0;34m([0m[0mself[0m[0;34m.[0m[0m_engine[0m[0;34m.[0m[0mon_success[0m[0;34m)[0m[0;34m[0m[0m
[0m[1;32m    180[0m             [0mresult[0m [0;34m=[0m [0mSuccess[0m[0;34m([0m[0mself[0m[0;34m,[0m [0mtime[0m[0;34m.[0m[0mtime[0m[0;34m([0m[0;34m)[0m [0;34m-[0m [0mstart_time[0m[0;34m)[0m[0;34m[0m[0m
[1;32m    181[0m         [0;32melse[0m[0;34m:[0m[0;34m[0m[0m

[0;32m/((( anything )))/story.py[0m in [0;36mrun_special_method[0;34m(self, method)[0m
[1;32m    158[0m [0;34m[0m[0m
[1;32m    159[0m             raise exceptions.OnSuccessException(
[0;32m--> 160[0;31m                 [0mstack_trace[0m[0;34m[0m[0m
[0m[1;32m    161[0m             )
[1;32m    162[0m [0;34m[0m[0m

[0;31mOnSuccessException[0m: Exception was raised in on_success method:

[1]: function '[1mon_success[0m'
  /((( anything )))/engine.py

    
        6 : 
        7 :     def on_success(self):
    --> [1m8[0m :         raise_example_exception()
        9 : 
    
    

[2]: function '[1mraise_example_exception[0m'
  /((( anything )))/code_that_does_things.py

    
        20 : 
        21 : def raise_example_exception(text=""):
    --> [1m22[0m :     raise ExampleException(text)
        23 : 
    
    

[31m[1mcode_that_does_things.ExampleException[0m
  [2m[31m
    This is a demonstration exception's docstring.

    It spreads across multiple lines.
    [0m
[31m[39m